Workbook

Sheet 2004~2025 시즌 결과
B1: 2015 | C1: 2016 | D1: 2017 | E1: 2018 | F1: 2019 | G1: 2020*코로나 | H1: 2021 | I1: 2022 | J1: 2023 | K1: 2024 | L1: 2025
A2: 가천대 | B2: - | C2: - | D2: *가입,탈퇴 | E2: - | F2: 버금8강 | G2: - | H2: 조별 | I2: 으뜸8강 | J2: 으뜸16강 | K2: 버금8강 | L2: 으뜸16강 | R2: <춘계리그> | T2: <추계리그>
A3: 가톨릭대 | B3: 버금16강 | C3: 버금16강 | D3: 버금8강 | E3: 버금16강 | F3: 조별 | G3: - | H3: 버금8강 | I3: 버금16강 | J3: 조별 | K3: 조별 | L3: 버금16강 | R3: 우승 | S3: 준우승 | T3: 우승 | U3: 준우승
A4: 강남대 | B4: 조별 | C4: 버금우승 | D4: 버금16강 | E4: 버금16강 | F4: *탈퇴 | G4: - | H4: - | I4: - | J4: - | K4: 조별 | L4: 버금16강 | Q4: 1981 | R4: 단국대죽전 | S4: 성균관대 | T4: 한국외국어대서울 | U4: 단국대죽전
A5: 건국대글로컬 | B5: 조별 | C5: 조별 | D5: 조별 | E5: 조별 | F5: 조별 | G5: - | H5: 버금16강 | I5: 으뜸16강 | J5: 으뜸16강 | K5: 버금16강 | L5: 버금8강 | Q5: 1982 | R5: 단국대죽전 | S5: 성균관대 | T5: 단국대죽전 | U5: 성균관대
A6: 건국대서울 | B6: 으뜸4강 | C6: 으뜸16강 | D6: 으뜸4강 | E6: 으뜸준우승 | F6: 으뜸4강 | G6: - | H6: 으뜸16강 | I6: 으뜸16강 | J6: 으뜸16강 | K6: 으뜸16강 | L6: 으뜸8강 | Q6: 1983 | R6: 한국외국어대서울 | S6: 단국대죽전 | T6: 단국대죽전 | U6: 홍익대
A7: 경기대 | B7: 버금8강 | C7: 으뜸8강 | D7: 버금16강 | E7: 으뜸16강 | F7: 으뜸준우승 | G7: - | H7: 으뜸우승 | I7: *으뜸8강 | J7: 버금16강 | K7: 으뜸16강 | L7: 으뜸16강 | Q7: 1984 | R7: 성균관대 | S7: 단국대죽전 | T7: 성균관대 | U7: 숭실대
A8: 경희대국제 | B8: 으뜸준우승 | C8: 으뜸준우승 | D8: 으뜸16강 | E8: 으뜸16강 | F8: 으뜸8강 | G8: - | H8: 으뜸4강 | I8: 으뜸8강 | J8: 으뜸8강 | K8: 으뜸16강 | L8: 으뜸4강 | Q8: 1985 | R8: 인하대 | S8: 한국외국어대글로벌 | T8: 한국외국어대서울 | U8: 성균관대
A9: 경희대서울 | B9: 으뜸16강 | C9: 으뜸4강 | D9: 버금4강 | E9: 버금16강 | F9: 으뜸16강 | G9: - | H9: 버금16강 | I9: 버금16강 | J9: 으뜸4강 | K9: 으뜸4강 | L9: 버금우승 | Q9: 1986 | R9: 한국외국어대서울 | S9: 아주대 | T9: 한국외국어대서울 | U9: 건국대서울
A10: 고려대 | B10: 으뜸16강 | C10: 버금16강 | D10: 버금16강 | E10: 으뜸8강 | F10: 버금8강 | G10: - | H10: 버금준우승 | I10: 버금준우승 | J10: 으뜸8강 | K10: 으뜸4강 | L10: 으뜸16강 | Q10: 1987 | R10: 단국대죽전 | S10: 성균관대 | T10: 동국대 | U10: 고려대
A11: 광운대 | B11: 버금16강 | C11: 버금8강 | D11: 으뜸16강 | E11: 버금16강 | F11: 버금4강 | G11: - | H11: 버금4강 | I11: 조별 | J11: 조별 | K11: 조별 | L11: 조별 | Q11: 1988 | R11: 동국대 | S11: 인하대 | T11: 고려대 | U11: 서강대
A12: 국민대 | B12: 버금16강 | C12: 버금16강 | D12: 으뜸8강 | E12: 조별 | F12: 버금16강 | G12: - | H12: 으뜸4강 | I12: 버금16강 | J12: 버금4강 | K12: 으뜸준우승 | L12: 버금16강 | Q12: 1989 | R12: 성균관대 | S12: 동국대 | T12: 단국대죽전 | U12: 한국외국어대서울
A13: 단국대죽전 | B13: 버금16강 | C13: 버금준우승 | D13: 으뜸8강 | E13: 버금8강 | F13: 버금8강 | G13: - | H13: 버금8강 | I13: 버금4강 | J13: 조별 | K13: 버금4강 | L13: 버금8강 | Q13: 1990 | R13: 한국외국어대서울 | S13: 성균관대 | T13: 동국대 | U13: 단국대죽전
A14: 단국대천안 | B14: 으뜸16강 | C14: 버금8강 | D14: 으뜸8강 | E14: 으뜸8강 | F14: 으뜸16강 | G14: - | H14: 버금16강 | I14: 으뜸16강 | J14: 버금16강 | K14: 으뜸16강 | L14: 버금16강 | Q14: 1991 | R14: 한양대에리카 | S14: 한국외국어대서울 | T14: 숭실대 | U14: 건국대서울
A15: 동국대 | B15: 조별 | C15: 으뜸16강 | D15: 으뜸16강 | E15: 으뜸16강 | F15: 버금16강 | G15: - | H15: 버금16강 | I15: 버금16강 | J15: 버금16강 | L15: 버금8강 | Q15: 1992 | R15: 한국외국어대서울 | S15: 단국대죽전 | T15: 한국외국어대서울 | U15: 건국대서울
A16: 명지대서울 | B16: 으뜸16강 | C16: 조별 | D16: 조별 | E16: 버금16강 | F16: 버금16강 | G16: - | H16: 버금16강 | I16: 조별 | J16: 버금4강 | K16: 버금준우승 | L16: 조별 | Q16: 1993 | R16: 중앙대서울 | S16: 동국대 | T16: 중앙대서울 | U16: 경희대서울
A17: 명지대용인 | B17: 버금16강 | C17: *탈퇴 | D17: 조별 | E17: 조별 | F17: 조별 | G17: - | H17: 으뜸8강 | I17: 조별 | J17: 조별 | K17: *탈퇴(몰수패) | L17: - | Q17: 1994 | R17: 건국대서울 | S17: 아주대 | T17: 한국항공대 | U17: 동국대
A18: 백석대 | B18: *자격정지 | C18: 버금16강 | D18: - | E18: - | F18: - | G18: *재가입 | H18: 불참*코로나 | I18: 으뜸16강 | J18: 버금16강 | K18: 으뜸16강 | L18: 버금16강 | Q18: 1995 | R18: 중앙대서울 | S18: 동국대 | T18: 한국항공대 | U18: 국민대
A19: 상명대 | B19: 으뜸8강 | C19: 버금8강 | D19: 으뜸16강 | E19: 으뜸16강 | F19: 으뜸16강 | G19: - | H19: 으뜸16강 | I19: 버금16강 | J19: 버금8강 | K19: 버금8강 | L19: 으뜸16강 | Q19: 1996 | R19: 중앙대서울 | S19: 서강대 | T19: 고려대 | U19: 홍익대
A20: 삼육대 | B20: - | C20: - | D20: - | E20: - | F20: - | G20: - | H20: - | I20: - | J20: - | K20: - | L20: - | Q20: 1997 | R20: 성균관대 | S20: 숭실대 | T20: 홍익대 | U20: 동국대
A21: 서강대 | B21: 으뜸16강 | C21: 으뜸16강 | D21: 으뜸16강 | E21: 버금4강 | F21: 버금16강 | G21: - | H21: 버금16강 | I21: 버금16강 | J21: 버금준우승 | K21: 조별 | L21: 으뜸8강 | Q21: 1998 | R21: 동국대 | S21: 경희대 | T21: 서울대 | U21: 한국외국어대서울
A22: 서경대 | B22: 버금16강 | C22: 버금16강 | D22: 버금16강 | E22: 조별 | F22: 버금16강 | G22: - | H22: 조별 | I22: *불참 | J22: 조별 | K22: 버금16강 | L22: 버금16강 | Q22: 1999 | R22: 광운대 | S22: 동국대 | T22: 인하대 | U22: 건국대서울
A23: 서일대 | B23: - | C23: - | D23: - | E23: 조별 | F23: 조별 | G23: - | H23: - | I23: - | J23: - | K23: - | L23: - | Q23: 2000 | R23: 연세대 | S23: 건국대서울 | T23: 연세대 | U23: 서울대
A24: 서울과학기술대 | B24: 으뜸우승 | C24: 으뜸16강 | D24: 으뜸우승 | E24: 으뜸우승 | F24: 으뜸8강 | G24: - | H24: 으뜸16강 | I24: 버금우승 | J24: 으뜸8강 | K24: 버금16강 | L24: 버금8강 | Q24: 2001 | R24: 건국대서울 | S24: 성균관대 | T24: 동국대 | U24: 광운대
A25: 서울대 | B25: - | C25: - | D25: - | E25: - | F25: - | G25: - | H25: - | I25: - | J25: - | K25: - | L25: - | R25: <단일리그>
A26: 서울시립대 | B26: 버금4강 | C26: 조별 | D26: 조별 | E26: 조별 | F26: 조별 | G26: - | H26: 으뜸8강 | I26: 버금8강 | J26: 버금8강 | K26: 버금8강 | L26: 으뜸준우승 | R26: 우승 | S26: 준우승
A27: 서울예술대 | B27: - | C27: - | D27: - | E27: - | F27: - | G27: - | H27: - | I27: - | J27: - | K27: - | L27: - | Q27: 2002 | R27: 동국대 | S27: 인하대
A28: 성균관대 | B28: 으뜸16강 | C28: 으뜸4강 | D28: 버금16강 | E28: 으뜸4강 | F28: 으뜸우승 | G28: - | H28: 으뜸8강 | I28: 으뜸16강 | J28: 으뜸16강 | K28: 버금16강 | L28: 조별 | Q28: 2003 | R28: 경희대국제 | S28: 광운대
A29: 세종대 | B29: 으뜸16강 | C29: 으뜸8강 | D29: 으뜸준우승 | E29: 으뜸16강 | F29: 으뜸8강 | G29: - | H29: 으뜸16강 | I29: 버금16강 | J29: 버금8강 | K29: 버금4강 | L29: 으뜸우승 | R29: <으뜸 토너먼트> | T29: <버금 토너먼트>
A30: 숭실대 | B30: 으뜸8강 | C30: 으뜸우승 | D30: 으뜸8강 | E30: 으뜸16강 | F30: 으뜸16강 | G30: - | H30: 으뜸8강 | I30: 으뜸16강 | J30: 으뜸준우승 | K30: 으뜸16강 | L30: 으뜸16강 | R30: 우승 | S30: 준우승 | T30: 우승 | U30: 준우승
A31: 아주대 | B31: 버금우승 | C31: 으뜸16강 | D31: 버금준우승 | E31: 버금8강 | F31: 조별 | G31: - | H31: 버금8강 | I31: *으뜸16강 | J31: *자격정지 | K31: 버금8강 | L31: 으뜸8강 | Q31: 2004 | R31: 홍익대 | S31: 광운대 | T31: - | U31: -
A32: 연세대 | B32: 으뜸8강 | C32: 으뜸16강 | D32: 조별 | E32: 으뜸8강 | F32: 으뜸16강 | G32: - | H32: 으뜸16강 | I32: 으뜸8강 | J32: 으뜸8강 | K32: 으뜸16강 | L32: 으뜸4강 | Q32: 2005 | R32: 동국대 | S32: 건국대서울 | T32: 한성대 | U32: 서울과학기술대
A33: 용인대 | B33: - | C33: - | D33: - | E33: - | F33: - | G33: - | H33: - | I33: 조별 | J33: - | K33: - | L33: - | Q33: 2006 | R33: 건국대서울 | S33: 국민대 | T33: 한성대 | U33: 숭실대
A34: 육군사관학교 | B34: 조별*조4위 | C34: - | D34: - | E34: - | F34: - | G34: - | H34: - | I34: - | J34: - | K34: - | L34: - | Q34: 2007 | R34: 경희대국제 | S34: 연세대 | T34: - | U34: -
A35: 인천대 | B35: 버금8강*조5위 | C35: 조별 | D35: 으뜸16강 | E35: 으뜸16강 | F35: 으뜸16강 | G35: - | H35: 조별 | I35: 버금4강 | J35: 으뜸16강 | K35: 으뜸8강 | L35: 버금16강 | Q35: 2008 | R35: 홍익대 | S35: 중앙대서울 | T35: 인하대 | U35: 광운대
A36: 인하대 | B36: 버금준우승 | C36: 으뜸8강 | D36: 버금16강 | E36: 으뜸16강 | F36: 버금우승 | G36: - | H36: 으뜸16강 | I36: 조별 | J36: 버금16강 | K36: 으뜸8강 | L36: 버금4강 | Q36: 2009 | R36: 연세대 | S36: 경희대국제 | T36: 상명대 OR 한양대 에리카
A37: 중앙대서울 | B37: 으뜸4강 | C37: 으뜸16강 | D37: 으뜸16강 | E37: 으뜸4강 | F37: 으뜸8강 | G37: - | H37: 버금우승 | I37: *으뜸4강 | J37: 으뜸16강 | K37: 으뜸8강 | L37: 으뜸16강 | Q37: 2010 | R37: 동국대 | S37: 서울과학기술대 | T37: 서강대 | U37: 한국외국어대글로벌
A38: 중앙대안성 | B38: 버금8강 | C38: 조별 | D38: - | E38: - | F38: - | G38: - | H38: - | I38: - | J38: - | K38: - | L38: - | Q38: 2011 | R38: 연세대 | S38: 중앙대서울 | T38: 경기대 | U38: 한양대서울
A39: 한국공학대 | B39: 조별 | C39: 버금16강 | D39: 버금우승 | E39: 으뜸8강 | F39: 으뜸4강 | G39: - | H39: 버금8강 | I39: 버금8강 | J39: 조별 | K39: 조별 | L39: 버금4강 | Q39: 2012 | R39: 서울과학기술대 | S39: 숭실대 | T39: 인천대 | U39: 한국외국어대글로벌
A40: 한국교통대 | B40: - | C40: - | D40: - | E40: 버금4강 | F40: 버금16강 | G40: - | H40: 버금4강 | I40: 으뜸16강 | J40: 버금16강 | K40: 조별 | L40: 조별 | Q40: 2013 | R40: 연세대 | S40: 숭실대 | T40: 고려대 | U40: 한성대
...

Sheet 역대 성적
A1: *1981년~2001년 춘계 추계 / 2002~2003 단일리그 / 2004~ 으뜸 버금 도입 / 2004,2007년 으뜸 우승 준우승팀만 확인가능/ 2009년 버금 우승팀 확인불가 (결승 대진 상명대vs한양대에리카로 추정) / 4강,8강,16강 횟수는 시즌 마무리 기준(중복X)
A2: *탈퇴한팀 - 명지대(용인) - 몰수패 심의(2024 탈퇴) / 삼육대-2012 탈퇴 예상 / 서울대-2013 탈퇴 예상 / 서울예술대-2006 탈퇴 예상 / 중앙대(안성)- 몰수패 심의 예상 (2017 탈퇴) / 한세대 - 2014 탈퇴 예상 / 육군사관학교 - 2016 탈퇴 예상 / 서일대 - 2020 탈퇴 예상 / 용인대 - 2023 탈퇴
A3: 팀명 | B3: 우승 | G3: 준우승 | L3: 으뜸우승 | M3: 으뜸준우승 | N3: 으뜸4강 | O3: 으뜸8강 | P3: 으뜸16강 | Q3: 버금 우승 | T3: 버금준우승 | W3: 버금4강 | X3: 버금8강 | Y3: 버금16강 | Z3: 버금32강 | AA3: 으뜸 | AB3: 버금 | AC3: 비고
A4: 가천대 | B4: - | G4: - | L4: {=SUMPRODUCT(ISNUMBER(FIND("으뜸우승", '2004~2025 시즌 결과'!$B2:$L2))*1)} -> 0 | M4: {=SUMPRODUCT(ISNUMBER(FIND("으뜸준우승", '2004~2025 시즌 결과'!$B2:$L2))*1)} -> 0 | N4: {=SUMPRODUCT(ISNUMBER(FIND("으뜸4강", '2004~2025 시즌 결과'!$B2:$L2))*1)} -> 0 | O4: {=SUMPRODUCT(ISNUMBER(FIND("으뜸8강", '2004~2025 시즌 결과'!$B2:$L2))*1)} -> 1 | P4: {=SUMPRODUCT(ISNUMBER(FIND("으뜸16강", '2004~2025 시즌 결과'!$B2:$L2))*1)} -> 2 | Q4: - | T4: - | W4: {=SUMPRODUCT(ISNUMBER(FIND("버금4강", '2004~2025 시즌 결과'!$B2:$L2))*1)} -> 0 | X4: {=SUMPRODUCT(ISNUMBER(FIND("버금8강", '2004~2025 시즌 결과'!$B2:$L2))*1)} -> 2 | Y4: {=SUMPRODUCT(ISNUMBER(FIND("버금16강", '2004~2025 시즌 결과'!$B2:$L2))*1)} -> 0 | Z4: {=SUM(COUNTIF('2004~2025 시즌 결과'!$B2:$L2, {"*버금23강*","*버금24강*","*버금32강*"}))} -> 0 | AA4: {=SUMPRODUCT(ISNUMBER(FIND("으뜸", '2004~2025 시즌 결과'!$B2:$L2))*1)} -> 3 | AB4: {=SUMPRODUCT(ISNUMBER(FIND("버금", '2004~2025 시즌 결과'!$B2:$L2))*1)} -> 2 | AG4: *최다 우승팀 - 동국대,한국외대(서울) (8회) *최다 준우승팀 - 건국대(서울), 성균관대 (7회) *으뜸 최다 우승팀 - 서울과학기술대 (4회) *으뜸 최다 준우승팀 - 경희대(국제), 숭실대, 중앙대(서울) (3회) *으뜸 최다 진츨팀 - 경희대(국제) (21회) *으뜸 버금 모두 우승한 팀 - 경기대, 동국대, 서울과기대, 한양대(서울)
A5: 가톨릭대 | B5: - | G5: - | L5: {=SUMPRODUCT(ISNUMBER(FIND("으뜸우승", '2004~2025 시즌 결과'!$B3:$L3))*1)} -> 0 | M5: {=SUMPRODUCT(ISNUMBER(FIND("으뜸준우승", '2004~2025 시즌 결과'!$B3:$L3))*1)} -> 0 | N5: {=SUMPRODUCT(ISNUMBER(FIND("으뜸4강", '2004~2025 시즌 결과'!$B3:$L3))*1)} -> 0 | O5: {=SUMPRODUCT(ISNUMBER(FIND("으뜸8강", '2004~2025 시즌 결과'!$B3:$L3))*1)} -> 0 | P5: {=SUMPRODUCT(ISNUMBER(FIND("으뜸16강", '2004~2025 시즌 결과'!$B3:$L3))*1)} -> 0 | Q5: - | T5: - | W5: {=SUMPRODUCT(ISNUMBER(FIND("버금4강", '2004~2025 시즌 결과'!$B3:$L3))*1)} -> 0 | X5: {=SUMPRODUCT(ISNUMBER(FIND("버금8강", '2004~2025 시즌 결과'!$B3:$L3))*1)} -> 2 | Y5: {=SUMPRODUCT(ISNUMBER(FIND("버금16강", '2004~2025 시즌 결과'!$B3:$L3))*1)} -> 5 | Z5: {=SUM(COUNTIF('2004~2025 시즌 결과'!$B3:$L3, {"*버금23강*","*버금24강*","*버금32강*"}))} -> 0 | AA5: {=SUMPRODUCT(ISNUMBER(FIND("으뜸", '2004~2025 시즌 결과'!$B3:$L3))*1)} -> 0 | AB5: {=SUMPRODUCT(ISNUMBER(FIND("버금", '2004~2025 시즌 결과'!$B3:$L3))*1)} -> 7
A6: 강남대 | B6: - | G6: - | L6: {=SUMPRODUCT(ISNUMBER(FIND("으뜸우승", '2004~2025 시즌 결과'!$B4:$L4))*1)} -> 0 | M6: {=SUMPRODUCT(ISNUMBER(FIND("으뜸준우승", '2004~2025 시즌 결과'!$B4:$L4))*1)} -> 0 | N6: {=SUMPRODUCT(ISNUMBER(FIND("으뜸4강", '2004~2025 시즌 결과'!$B4:$L4))*1)} -> 0 | O6: {=SUMPRODUCT(ISNUMBER(FIND("으뜸8강", '2004~2025 시즌 결과'!$B4:$L4))*1)} -> 0 | P6: {=SUMPRODUCT(ISNUMBER(FIND("으뜸16강", '2004~2025 시즌 결과'!$B4:$L4))*1)} -> 0 | Q6: 1회*(2016) | T6: - | W6: {=SUMPRODUCT(ISNUMBER(FIND("버금4강", '2004~2025 시즌 결과'!$B4:$L4))*1)} -> 0 | X6: {=SUMPRODUCT(ISNUMBER(FIND("버금8강", '2004~2025 시즌 결과'!$B4:$L4))*1)} -> 0 | Y6: {=SUMPRODUCT(ISNUMBER(FIND("버금16강", '2004~2025 시즌 결과'!$B4:$L4))*1)} -> 3 | Z6: {=SUM(COUNTIF('2004~2025 시즌 결과'!$B4:$L4, {"*버금23강*","*버금24강*","*버금32강*"}))} -> 0 | AA6: {=SUMPRODUCT(ISNUMBER(FIND("으뜸", '2004~2025 시즌 결과'!$B4:$L4))*1)} -> 0 | AB6: {=SUMPRODUCT(ISNUMBER(FIND("버금", '2004~2025 시즌 결과'!$B4:$L4))*1)} -> 4 | AC6: *(2004,2005,2007 버금)
A7: 건국대글로컬 | B7: - | G7: - | L7: {=SUMPRODUCT(ISNUMBER(FIND("으뜸우승", '2004~2025 시즌 결과'!$B5:$L5))*1)} -> 0 | M7: {=SUMPRODUCT(ISNUMBER(FIND("으뜸준우승", '2004~2025 시즌 결과'!$B5:$L5))*1)} -> 0 | N7: {=SUMPRODUCT(ISNUMBER(FIND("으뜸4강", '2004~2025 시즌 결과'!$B5:$L5))*1)} -> 0 | O7: {=SUMPRODUCT(ISNUMBER(FIND("으뜸8강", '2004~2025 시즌 결과'!$B5:$L5))*1)} -> 0 | P7: {=SUMPRODUCT(ISNUMBER(FIND("으뜸16강", '2004~2025 시즌 결과'!$B5:$L5))*1)} -> 2 | Q7: - | T7: - | W7: {=SUMPRODUCT(ISNUMBER(FIND("버금4강", '2004~2025 시즌 결과'!$B5:$L5))*1)} -> 0 | X7: {=SUMPRODUCT(ISNUMBER(FIND("버금8강", '2004~2025 시즌 결과'!$B5:$L5))*1)} -> 1 | Y7: {=SUMPRODUCT(ISNUMBER(FIND("버금16강", '2004~2025 시즌 결과'!$B5:$L5))*1)} -> 2 | Z7: {=SUM(COUNTIF('2004~2025 시즌 결과'!$B5:$L5, {"*버금23강*","*버금24강*","*버금32강*"}))} -> 0 | AA7: {=SUMPRODUCT(ISNUMBER(FIND("으뜸", '2004~2025 시즌 결과'!$B5:$L5))*1)} -> 2 | AB7: {=SUMPRODUCT(ISNUMBER(FIND("버금", '2004~2025 시즌 결과'!$B5:$L5))*1)} -> 3 | AC7: *(2004,2007 버금)
A8: 건국대서울 | B8: 3회*(1994춘계,2001춘계,2006) | G8: 7회*(1986추계,1991추계,1992추계,1999추계,2000춘계,2005,2018) | L8: {=SUMPRODUCT(ISNUMBER(FIND("으뜸우승", '2004~2025 시즌 결과'!$B6:$L6))*1)} -> 0 | M8: {=SUMPRODUCT(ISNUMBER(FIND("으뜸준우승", '2004~2025 시즌 결과'!$B6:$L6))*1)} -> 1 | N8: {=SUMPRODUCT(ISNUMBER(FIND("으뜸4강", '2004~2025 시즌 결과'!$B6:$L6))*1)} -> 3 | O8: {=SUMPRODUCT(ISNUMBER(FIND("으뜸8강", '2004~2025 시즌 결과'!$B6:$L6))*1)} -> 1 | P8: {=SUMPRODUCT(ISNUMBER(FIND("으뜸16강", '2004~2025 시즌 결과'!$B6:$L6))*1)} -> 5 | Q8: - | T8: - | W8: {=SUMPRODUCT(ISNUMBER(FIND("버금4강", '2004~2025 시즌 결과'!$B6:$L6))*1)} -> 0 | X8: {=SUMPRODUCT(ISNUMBER(FIND("버금8강", '2004~2025 시즌 결과'!$B6:$L6))*1)} -> 0 | Y8: {=SUMPRODUCT(ISNUMBER(FIND("버금16강", '2004~2025 시즌 결과'!$B6:$L6))*1)} -> 0 | Z8: {=SUM(COUNTIF('2004~2025 시즌 결과'!$B6:$L6, {"*버금23강*","*버금24강*","*버금32강*"}))} -> 0 | AA8: {=SUMPRODUCT(ISNUMBER(FIND("으뜸", '2004~2025 시즌 결과'!$B6:$L6))*1)} -> 10 | AB8: {=SUMPRODUCT(ISNUMBER(FIND("버금", '2004~2025 시즌 결과'!$B6:$L6))*1)} -> 0 | AC8: *(2004 으뜸, 2007 버금)
A9: 경기대 | B9: 1회*(2021) | G9: 1회*(2019) | L9: {=SUMPRODUCT(ISNUMBER(FIND("으뜸우승", '2004~2025 시즌 결과'!$B7:$L7))*1)} -> 1 | M9: {=SUMPRODUCT(ISNUMBER(FIND("으뜸준우승", '2004~2025 시즌 결과'!$B7:$L7))*1)} -> 1 | N9: {=SUMPRODUCT(ISNUMBER(FIND("으뜸4강", '2004~2025 시즌 결과'!$B7:$L7))*1)} -> 0 | O9: {=SUMPRODUCT(ISNUMBER(FIND("으뜸8강", '2004~2025 시즌 결과'!$B7:$L7))*1)} -> 2 | P9: {=SUMPRODUCT(ISNUMBER(FIND("으뜸16강", '2004~2025 시즌 결과'!$B7:$L7))*1)} -> 3 | Q9: 1회*(2011) | T9: - | W9: {=SUMPRODUCT(ISNUMBER(FIND("버금4강", '2004~2025 시즌 결과'!$B7:$L7))*1)} -> 0 | X9: {=SUMPRODUCT(ISNUMBER(FIND("버금8강", '2004~2025 시즌 결과'!$B7:$L7))*1)} -> 1 | Y9: {=SUMPRODUCT(ISNUMBER(FIND("버금16강", '2004~2025 시즌 결과'!$B7:$L7))*1)} -> 2 | Z9: {=SUM(COUNTIF('2004~2025 시즌 결과'!$B7:$L7, {"*버금23강*","*버금24강*","*버금32강*"}))} -> 0 | AA9: {=SUMPRODUCT(ISNUMBER(FIND("으뜸", '2004~2025 시즌 결과'!$B7:$L7))*1)} -> 7 | AB9: {=SUMPRODUCT(ISNUMBER(FIND("버금", '2004~2025 시즌 결과'!$B7:$L7))*1)} -> 3 | AC9: *(2004 버금, 2007 으뜸)
A10: 경희대국제 | B10: 3회*(2003,2007,2014) | G10: 3회*(2009,2015,2016) | J10: 1회*(1998춘계)-캠퍼스명시X | L10: {=SUMPRODUCT(ISNUMBER(FIND("으뜸우승", '2004~2025 시즌 결과'!$B8:$L8))*1)} -> 0 | M10: {=SUMPRODUCT(ISNUMBER(FIND("으뜸준우승", '2004~2025 시즌 결과'!$B8:$L8))*1)} -> 2 | N10: {=SUMPRODUCT(ISNUMBER(FIND("으뜸4강", '2004~2025 시즌 결과'!$B8:$L8))*1)} -> 2 | O10: {=SUMPRODUCT(ISNUMBER(FIND("으뜸8강", '2004~2025 시즌 결과'!$B8:$L8))*1)} -> 3 | P10: {=SUMPRODUCT(ISNUMBER(FIND("으뜸16강", '2004~2025 시즌 결과'!$B8:$L8))*1)} -> 3 | Q10: - | T10: - | W10: {=SUMPRODUCT(ISNUMBER(FIND("버금4강", '2004~2025 시즌 결과'!$B8:$L8))*1)} -> 0 | X10: {=SUMPRODUCT(ISNUMBER(FIND("버금8강", '2004~2025 시즌 결과'!$B8:$L8))*1)} -> 0 | Y10: {=SUMPRODUCT(ISNUMBER(FIND("버금16강", '2004~2025 시즌 결과'!$B8:$L8))*1)} -> 0 | Z10: {=SUM(COUNTIF('2004~2025 시즌 결과'!$B8:$L8, {"*버금23강*","*버금24강*","*버금32강*"}))} -> 0 | AA10: {=SUMPRODUCT(ISNUMBER(FIND("으뜸", '2004~2025 시즌 결과'!$B8:$L8))*1)} -> 10 | AB10: {=SUMPRODUCT(ISNUMBER(FIND("버금", '2004~2025 시즌 결과'!$B8:$L8))*1)} -> 0 | AC10: *(2004 으뜸) / 으뜸 4강 진행중
A11: 경희대서울 | B11: - | G11: 1회*(1993추계) | L11: {=SUMPRODUCT(ISNUMBER(FIND("으뜸우승", '2004~2025 시즌 결과'!$B9:$L9))*1)} -> 0 | M11: {=SUMPRODUCT(ISNUMBER(FIND("으뜸준우승", '2004~2025 시즌 결과'!$B9:$L9))*1)} -> 0 | N11: {=SUMPRODUCT(ISNUMBER(FIND("으뜸4강", '2004~2025 시즌 결과'!$B9:$L9))*1)} -> 3 | O11: {=SUMPRODUCT(ISNUMBER(FIND("으뜸8강", '2004~2025 시즌 결과'!$B9:$L9))*1)} -> 0 | P11: {=SUMPRODUCT(ISNUMBER(FIND("으뜸16강", '2004~2025 시즌 결과'!$B9:$L9))*1)} -> 2 | Q11: 1회(*2025) | T11: - | W11: {=SUMPRODUCT(ISNUMBER(FIND("버금4강", '2004~2025 시즌 결과'!$B9:$L9))*1)} -> 1 | X11: {=SUMPRODUCT(ISNUMBER(FIND("버금8강", '2004~2025 시즌 결과'!$B9:$L9))*1)} -> 0 | Y11: {=SUMPRODUCT(ISNUMBER(FIND("버금16강", '2004~2025 시즌 결과'!$B9:$L9))*1)} -> 3 | Z11: {=SUM(COUNTIF('2004~2025 시즌 결과'!$B9:$L9, {"*버금23강*","*버금24강*","*버금32강*"}))} -> 0 | AA11: {=SUMPRODUCT(ISNUMBER(FIND("으뜸", '2004~2025 시즌 결과'!$B9:$L9))*1)} -> 5 | AB11: {=SUMPRODUCT(ISNUMBER(FIND("버금", '2004~2025 시즌 결과'!$B9:$L9))*1)} -> 5 | AC11: *(2004 으뜸, 2005,2007 버금) / 버금 4강 진행중 | AG11: *버금 최다 우승팀 - 인하대, 한국공학대, 한성대 (3회) *버금 최다 준우승팀 - 고려대, 광운대, 한국외대(글로벌) (2회) *최다 버금 진출팀 - 한국외대(글로벌), 한성대, 한신대 (16회) *으뜸 미진출팀(현재 참가교) - 가톨릭대 ,강남대, 서경대 *버금 미진출팀(현재 참가교) - 경희대(국제)
A12: 고려대 | B12: 2회*(1988추계,1996추계) | G12: 1회*(1987추계) | L12: {=SUMPRODUCT(ISNUMBER(FIND("으뜸우승", '2004~2025 시즌 결과'!$B10:$L10))*1)} -> 0 | M12: {=SUMPRODUCT(ISNUMBER(FIND("으뜸준우승", '2004~2025 시즌 결과'!$B10:$L10))*1)} -> 0 | N12: {=SUMPRODUCT(ISNUMBER(FIND("으뜸4강", '2004~2025 시즌 결과'!$B10:$L10))*1)} -> 1 | O12: {=SUMPRODUCT(ISNUMBER(FIND("으뜸8강", '2004~2025 시즌 결과'!$B10:$L10))*1)} -> 2 | P12: {=SUMPRODUCT(ISNUMBER(FIND("으뜸16강", '2004~2025 시즌 결과'!$B10:$L10))*1)} -> 2 | Q12: 1회*(2013) | T12: 2회*(2021,2022) | W12: {=SUMPRODUCT(ISNUMBER(FIND("버금4강", '2004~2025 시즌 결과'!$B10:$L10))*1)} -> 0 | X12: {=SUMPRODUCT(ISNUMBER(FIND("버금8강", '2004~2025 시즌 결과'!$B10:$L10))*1)} -> 1 | Y12: {=SUMPRODUCT(ISNUMBER(FIND("버금16강", '2004~2025 시즌 결과'!$B10:$L10))*1)} -> 2 | Z12: {=SUM(COUNTIF('2004~2025 시즌 결과'!$B10:$L10, {"*버금23강*","*버금24강*","*버금32강*"}))} -> 0 | AA12: {=SUMPRODUCT(ISNUMBER(FIND("으뜸", '2004~2025 시즌 결과'!$B10:$L10))*1)} -> 5 | AB12: {=SUMPRODUCT(ISNUMBER(FIND("버금", '2004~2025 시즌 결과'!$B10:$L10))*1)} -> 5 | AC12: *(2004,2007 으뜸)
A13: 광운대 | B13: 1회*(1999춘계) | G13: 3회*(2001추계,2003,2004) | L13: {=SUMPRODUCT(ISNUMBER(FIND("으뜸우승", '2004~2025 시즌 결과'!$B11:$L11))*1)} -> 0 | M13: {=SUMPRODUCT(ISNUMBER(FIND("으뜸준우승", '2004~2025 시즌 결과'!$B11:$L11))*1)} -> 0 | N13: {=SUMPRODUCT(ISNUMBER(FIND("으뜸4강", '2004~2025 시즌 결과'!$B11:$L11))*1)} -> 0 | O13: {=SUMPRODUCT(ISNUMBER(FIND("으뜸8강", '2004~2025 시즌 결과'!$B11:$L11))*1)} -> 0 | P13: {=SUMPRODUCT(ISNUMBER(FIND("으뜸16강", '2004~2025 시즌 결과'!$B11:$L11))*1)} -> 1 | Q13: - | T13: 2회*(2008,2014) | W13: {=SUMPRODUCT(ISNUMBER(FIND("버금4강", '2004~2025 시즌 결과'!$B11:$L11))*1)} -> 2 | X13: {=SUMPRODUCT(ISNUMBER(FIND("버금8강", '2004~2025 시즌 결과'!$B11:$L11))*1)} -> 1 | Y13: {=SUMPRODUCT(ISNUMBER(FIND("버금16강", '2004~2025 시즌 결과'!$B11:$L11))*1)} -> 2 | Z13: {=SUM(COUNTIF('2004~2025 시즌 결과'!$B11:$L11, {"*버금23강*","*버금24강*","*버금32강*"}))} -> 0 | AA13: {=SUMPRODUCT(ISNUMBER(FIND("으뜸", '2004~2025 시즌 결과'!$B11:$L11))*1)} -> 1 | AB13: {=SUMPRODUCT(ISNUMBER(FIND("버금", '2004~2025 시즌 결과'!$B11:$L11))*1)} -> 5 | AC13: *(2007 으뜸)
A14: 국민대 | B14: - | G14: 3회*(1995추계,2006,2024) | L14: {=SUMPRODUCT(ISNUMBER(FIND("으뜸우승", '2004~2025 시즌 결과'!$B12:$L12))*1)} -> 0 | M14: {=SUMPRODUCT(ISNUMBER(FIND("으뜸준우승", '2004~2025 시즌 결과'!$B12:$L12))*1)} -> 1 | N14: {=SUMPRODUCT(ISNUMBER(FIND("으뜸4강", '2004~2025 시즌 결과'!$B12:$L12))*1)} -> 1 | O14: {=SUMPRODUCT(ISNUMBER(FIND("으뜸8강", '2004~2025 시즌 결과'!$B12:$L12))*1)} -> 1 | P14: {=SUMPRODUCT(ISNUMBER(FIND("으뜸16강", '2004~2025 시즌 결과'!$B12:$L12))*1)} -> 0 | Q14: - | T14: - | W14: {=SUMPRODUCT(ISNUMBER(FIND("버금4강", '2004~2025 시즌 결과'!$B12:$L12))*1)} -> 1 | X14: {=SUMPRODUCT(ISNUMBER(FIND("버금8강", '2004~2025 시즌 결과'!$B12:$L12))*1)} -> 0 | Y14: {=SUMPRODUCT(ISNUMBER(FIND("버금16강", '2004~2025 시즌 결과'!$B12:$L12))*1)} -> 5 | Z14: {=SUM(COUNTIF('2004~2025 시즌 결과'!$B12:$L12, {"*버금23강*","*버금24강*","*버금32강*"}))} -> 0 | AA14: {=SUMPRODUCT(ISNUMBER(FIND("으뜸", '2004~2025 시즌 결과'!$B12:$L12))*1)} -> 3 | AB14: {=SUMPRODUCT(ISNUMBER(FIND("버금", '2004~2025 시즌 결과'!$B12:$L12))*1)} -> 6 | AC14: *(2004 버금, 2007 으뜸)
A15: 단국대죽전 | B15: 6회*(1981춘계,1982춘계,1982추계,1983추계,1987춘계,1989추계) | G15: 5회*(1981추계,1983춘계,1984춘계,1990추계,1992춘계) | L15: {=SUMPRODUCT(ISNUMBER(FIND("으뜸우승", '2004~2025 시즌 결과'!$B13:$L13))*1)} -> 0 | M15: {=SUMPRODUCT(ISNUMBER(FIND("으뜸준우승", '2004~2025 시즌 결과'!$B13:$L13))*1)} -> 0 | N15: {=SUMPRODUCT(ISNUMBER(FIND("으뜸4강", '2004~2025 시즌 결과'!$B13:$L13))*1)} -> 0 | O15: {=SUMPRODUCT(ISNUMBER(FIND("으뜸8강", '2004~2025 시즌 결과'!$B13:$L13))*1)} -> 1 | P15: {=SUMPRODUCT(ISNUMBER(FIND("으뜸16강", '2004~2025 시즌 결과'!$B13:$L13))*1)} -> 0 | Q15: - | T15: 1회*(2016) | W15: {=SUMPRODUCT(ISNUMBER(FIND("버금4강", '2004~2025 시즌 결과'!$B13:$L13))*1)} -> 2 | X15: {=SUMPRODUCT(ISNUMBER(FIND("버금8강", '2004~2025 시즌 결과'!$B13:$L13))*1)} -> 4 | Y15: {=SUMPRODUCT(ISNUMBER(FIND("버금16강", '2004~2025 시즌 결과'!$B13:$L13))*1)} -> 1 | Z15: {=SUM(COUNTIF('2004~2025 시즌 결과'!$B13:$L13, {"*버금23강*","*버금24강*","*버금32강*"}))} -> 0 | AA15: {=SUMPRODUCT(ISNUMBER(FIND("으뜸", '2004~2025 시즌 결과'!$B13:$L13))*1)} -> 1 | AB15: {=SUMPRODUCT(ISNUMBER(FIND("버금", '2004~2025 시즌 결과'!$B13:$L13))*1)} -> 8 | AC15: *(2004 으뜸, 2007 버금)
A16: 단국대천안 | B16: - | G16: - | L16: {=SUMPRODUCT(ISNUMBER(FIND("으뜸우승", '2004~2025 시즌 결과'!$B14:$L14))*1)} -> 0 | M16: {=SUMPRODUCT(ISNUMBER(FIND("으뜸준우승", '2004~2025 시즌 결과'!$B14:$L14))*1)} -> 0 | N16: {=SUMPRODUCT(ISNUMBER(FIND("으뜸4강", '2004~2025 시즌 결과'!$B14:$L14))*1)} -> 0 | O16: {=SUMPRODUCT(ISNUMBER(FIND("으뜸8강", '2004~2025 시즌 결과'!$B14:$L14))*1)} -> 2 | P16: {=SUMPRODUCT(ISNUMBER(FIND("으뜸16강", '2004~2025 시즌 결과'!$B14:$L14))*1)} -> 4 | Q16: - | T16: - | W16: {=SUMPRODUCT(ISNUMBER(FIND("버금4강", '2004~2025 시즌 결과'!$B14:$L14))*1)} -> 0 | X16: {=SUMPRODUCT(ISNUMBER(FIND("버금8강", '2004~2025 시즌 결과'!$B14:$L14))*1)} -> 1 | Y16: {=SUMPRODUCT(ISNUMBER(FIND("버금16강", '2004~2025 시즌 결과'!$B14:$L14))*1)} -> 3 | Z16: {=SUM(COUNTIF('2004~2025 시즌 결과'!$B14:$L14, {"*버금23강*","*버금24강*","*버금32강*"}))} -> 0 | AA16: {=SUMPRODUCT(ISNUMBER(FIND("으뜸", '2004~2025 시즌 결과'!$B14:$L14))*1)} -> 6 | AB16: {=SUMPRODUCT(ISNUMBER(FIND("버금", '2004~2025 시즌 결과'!$B14:$L14))*1)} -> 4 | AC16: *(2004,2007 버금)
A17: 동국대 | B17: 8회*(1987추계,1988춘계,1990추계,1998춘계,2001추계,2002,2005,2010) | G17: 6회*(1989춘계,1993춘계,1994추계,1995춘계,1997추계,1999춘계) | L17: {=SUMPRODUCT(ISNUMBER(FIND("으뜸우승", '2004~2025 시즌 결과'!$B15:$L15))*1)} -> 0 | M17: {=SUMPRODUCT(ISNUMBER(FIND("으뜸준우승", '2004~2025 시즌 결과'!$B15:$L15))*1)} -> 0 | N17: {=SUMPRODUCT(ISNUMBER(FIND("으뜸4강", '2004~2025 시즌 결과'!$B15:$L15))*1)} -> 0 | O17: {=SUMPRODUCT(ISNUMBER(FIND("으뜸8강", '2004~2025 시즌 결과'!$B15:$L15))*1)} -> 0 | P17: {=SUMPRODUCT(ISNUMBER(FIND("으뜸16강", '2004~2025 시즌 결과'!$B15:$L15))*1)} -> 3 | Q17: 1회*(2024) | T17: - | W17: {=SUMPRODUCT(ISNUMBER(FIND("버금4강", '2004~2025 시즌 결과'!$B15:$L15))*1)} -> 0 | X17: {=SUMPRODUCT(ISNUMBER(FIND("버금8강", '2004~2025 시즌 결과'!$B15:$L15))*1)} -> 1 | Y17: {=SUMPRODUCT(ISNUMBER(FIND("버금16강", '2004~2025 시즌 결과'!$B15:$L15))*1)} -> 4 | Z17: {=SUM(COUNTIF('2004~2025 시즌 결과'!$B15:$L15, {"*버금23강*","*버금24강*","*버금32강*"}))} -> 0 | AA17: {=SUMPRODUCT(ISNUMBER(FIND("으뜸", '2004~2025 시즌 결과'!$B15:$L15))*1)} -> 3 | AB17: {=SUMPRODUCT(ISNUMBER(FIND("버금", '2004~2025 시즌 결과'!$B15:$L15))*1)} -> 5 | AC17: *(2004,2007 으뜸)
A18: 명지대서울 | B18: - | G18: - | L18: {=SUMPRODUCT(ISNUMBER(FIND("으뜸우승", '2004~2025 시즌 결과'!$B16:$L16))*1)} -> 0 | M18: {=SUMPRODUCT(ISNUMBER(FIND("으뜸준우승", '2004~2025 시즌 결과'!$B16:$L16))*1)} -> 0 | N18: {=SUMPRODUCT(ISNUMBER(FIND("으뜸4강", '2004~2025 시즌 결과'!$B16:$L16))*1)} -> 0 | O18: {=SUMPRODUCT(ISNUMBER(FIND("으뜸8강", '2004~2025 시즌 결과'!$B16:$L16))*1)} -> 0 | P18: {=SUMPRODUCT(ISNUMBER(FIND("으뜸16강", '2004~2025 시즌 결과'!$B16:$L16))*1)} -> 1 | Q18: - | T18: 1회*(2024) | W18: {=SUMPRODUCT(ISNUMBER(FIND("버금4강", '2004~2025 시즌 결과'!$B16:$L16))*1)} -> 1 | X18: {=SUMPRODUCT(ISNUMBER(FIND("버금8강", '2004~2025 시즌 결과'!$B16:$L16))*1)} -> 0 | Y18: {=SUMPRODUCT(ISNUMBER(FIND("버금16강", '2004~2025 시즌 결과'!$B16:$L16))*1)} -> 3 | Z18: {=SUM(COUNTIF('2004~2025 시즌 결과'!$B16:$L16, {"*버금23강*","*버금24강*","*버금32강*"}))} -> 0 | AA18: {=SUMPRODUCT(ISNUMBER(FIND("으뜸", '2004~2025 시즌 결과'!$B16:$L16))*1)} -> 1 | AB18: {=SUMPRODUCT(ISNUMBER(FIND("버금", '2004~2025 시즌 결과'!$B16:$L16))*1)} -> 5 | AC18: *(2004,2007 버금)
A19: 명지대용인 | B19: - | G19: - | L19: {=SUMPRODUCT(ISNUMBER(FIND("으뜸우승", '2004~2025 시즌 결과'!$B17:$L17))*1)} -> 0 | M19: {=SUMPRODUCT(ISNUMBER(FIND("으뜸준우승", '2004~2025 시즌 결과'!$B17:$L17))*1)} -> 0 | N19: {=SUMPRODUCT(ISNUMBER(FIND("으뜸4강", '2004~2025 시즌 결과'!$B17:$L17))*1)} -> 0 | O19: {=SUMPRODUCT(ISNUMBER(FIND("으뜸8강", '2004~2025 시즌 결과'!$B17:$L17))*1)} -> 1 | P19: {=SUMPRODUCT(ISNUMBER(FIND("으뜸16강", '2004~2025 시즌 결과'!$B17:$L17))*1)} -> 0 | Q19: - | T19: - | W19: {=SUMPRODUCT(ISNUMBER(FIND("버금4강", '2004~2025 시즌 결과'!$B17:$L17))*1)} -> 0 | X19: {=SUMPRODUCT(ISNUMBER(FIND("버금8강", '2004~2025 시즌 결과'!$B17:$L17))*1)} -> 0 | Y19: {=SUMPRODUCT(ISNUMBER(FIND("버금16강", '2004~2025 시즌 결과'!$B17:$L17))*1)} -> 1 | Z19: {=SUM(COUNTIF('2004~2025 시즌 결과'!$B17:$L17, {"*버금23강*","*버금24강*","*버금32강*"}))} -> 0 | AA19: {=SUMPRODUCT(ISNUMBER(FIND("으뜸", '2004~2025 시즌 결과'!$B17:$L17))*1)} -> 1 | AB19: {=SUMPRODUCT(ISNUMBER(FIND("버금", '2004~2025 시즌 결과'!$B17:$L17))*1)} -> 1 | AC19: *(2004,2007 으뜸) / *탈퇴
A20: 백석대 | B20: - | G20: - | L20: {=SUMPRODUCT(ISNUMBER(FIND("으뜸우승", '2004~2025 시즌 결과'!$B18:$L18))*1)} -> 0 | M20: {=SUMPRODUCT(ISNUMBER(FIND("으뜸준우승", '2004~2025 시즌 결과'!$B18:$L18))*1)} -> 0 | N20: {=SUMPRODUCT(ISNUMBER(FIND("으뜸4강", '2004~2025 시즌 결과'!$B18:$L18))*1)} -> 0 | O20: {=SUMPRODUCT(ISNUMBER(FIND("으뜸8강", '2004~2025 시즌 결과'!$B18:$L18))*1)} -> 0 | P20: {=SUMPRODUCT(ISNUMBER(FIND("으뜸16강", '2004~2025 시즌 결과'!$B18:$L18))*1)} -> 2 | Q20: - | T20: - | W20: {=SUMPRODUCT(ISNUMBER(FIND("버금4강", '2004~2025 시즌 결과'!$B18:$L18))*1)} -> 0 | X20: {=SUMPRODUCT(ISNUMBER(FIND("버금8강", '2004~2025 시즌 결과'!$B18:$L18))*1)} -> 0 | Y20: {=SUMPRODUCT(ISNUMBER(FIND("버금16강", '2004~2025 시즌 결과'!$B18:$L18))*1)} -> 3 | Z20: {=SUM(COUNTIF('2004~2025 시즌 결과'!$B18:$L18, {"*버금23강*","*버금24강*","*버금32강*"}))} -> 0 | AA20: {=SUMPRODUCT(ISNUMBER(FIND("으뜸", '2004~2025 시즌 결과'!$B18:$L18))*1)} -> 2 | AB20: {=SUMPRODUCT(ISNUMBER(FIND("버금", '2004~2025 시즌 결과'!$B18:$L18))*1)} -> 3 | AC20: *(2004,2007 버금)
A21: 상명대 | B21: - | G21: - | L21: {=SUMPRODUCT(ISNUMBER(FIND("으뜸우승", '2004~2025 시즌 결과'!$B19:$L19))*1)} -> 0 | M21: {=SUMPRODUCT(ISNUMBER(FIND("으뜸준우승", '2004~2025 시즌 결과'!$B19:$L19))*1)} -> 0 | N21: {=SUMPRODUCT(ISNUMBER(FIND("으뜸4강", '2004~2025 시즌 결과'!$B19:$L19))*1)} -> 0 | O21: {=SUMPRODUCT(ISNUMBER(FIND("으뜸8강", '2004~2025 시즌 결과'!$B19:$L19))*1)} -> 1 | P21: {=SUMPRODUCT(ISNUMBER(FIND("으뜸16강", '2004~2025 시즌 결과'!$B19:$L19))*1)} -> 5 | Q21: - | T21: - | W21: {=SUMPRODUCT(ISNUMBER(FIND("버금4강", '2004~2025 시즌 결과'!$B19:$L19))*1)} -> 0 | X21: {=SUMPRODUCT(ISNUMBER(FIND("버금8강", '2004~2025 시즌 결과'!$B19:$L19))*1)} -> 3 | Y21: {=SUMPRODUCT(ISNUMBER(FIND("버금16강", '2004~2025 시즌 결과'!$B19:$L19))*1)} -> 1 | Z21: {=SUM(COUNTIF('2004~2025 시즌 결과'!$B19:$L19, {"*버금23강*","*버금24강*","*버금32강*"}))} -> 0 | AA21: {=SUMPRODUCT(ISNUMBER(FIND("으뜸", '2004~2025 시즌 결과'!$B19:$L19))*1)} -> 6 | AB21: {=SUMPRODUCT(ISNUMBER(FIND("버금", '2004~2025 시즌 결과'!$B19:$L19))*1)} -> 4 | AC21: *(2007 버금) / 2009년 버금 우승팀 확인불가 (결승 대진 상명대vs한양대에리카로 추정)
A22: 삼육대 | B22: - | G22: - | L22: {=SUMPRODUCT(ISNUMBER(FIND("으뜸우승", '2004~2025 시즌 결과'!$B20:$L20))*1)} -> 0 | M22: {=SUMPRODUCT(ISNUMBER(FIND("으뜸준우승", '2004~2025 시즌 결과'!$B20:$L20))*1)} -> 0 | N22: {=SUMPRODUCT(ISNUMBER(FIND("으뜸4강", '2004~2025 시즌 결과'!$B20:$L20))*1)} -> 0 | O22: {=SUMPRODUCT(ISNUMBER(FIND("으뜸8강", '2004~2025 시즌 결과'!$B20:$L20))*1)} -> 0 | P22: {=SUMPRODUCT(ISNUMBER(FIND("으뜸16강", '2004~2025 시즌 결과'!$B20:$L20))*1)} -> 0 | Q22: - | T22: - | W22: {=SUMPRODUCT(ISNUMBER(FIND("버금4강", '2004~2025 시즌 결과'!$B20:$L20))*1)} -> 0 | X22: {=SUMPRODUCT(ISNUMBER(FIND("버금8강", '2004~2025 시즌 결과'!$B20:$L20))*1)} -> 0 | Y22: {=SUMPRODUCT(ISNUMBER(FIND("버금16강", '2004~2025 시즌 결과'!$B20:$L20))*1)} -> 0 | Z22: {=SUM(COUNTIF('2004~2025 시즌 결과'!$B20:$L20, {"*버금23강*","*버금24강*","*버금32강*"}))} -> 0 | AA22: {=SUMPRODUCT(ISNUMBER(FIND("으뜸", '2004~2025 시즌 결과'!$B20:$L20))*1)} -> 0 | AB22: {=SUMPRODUCT(ISNUMBER(FIND("버금", '2004~2025 시즌 결과'!$B20:$L20))*1)} -> 0 | AC22: *탈퇴
A23: 서강대 | B23: - | G23: 2회*(1988추계,1996춘계) | L23: {=SUMPRODUCT(ISNUMBER(FIND("으뜸우승", '2004~2025 시즌 결과'!$B21:$L21))*1)} -> 0 | M23: {=SUMPRODUCT(ISNUMBER(FIND("으뜸준우승", '2004~2025 시즌 결과'!$B21:$L21))*1)} -> 0 | N23: {=SUMPRODUCT(ISNUMBER(FIND("으뜸4강", '2004~2025 시즌 결과'!$B21:$L21))*1)} -> 0 | O23: {=SUMPRODUCT(ISNUMBER(FIND("으뜸8강", '2004~2025 시즌 결과'!$B21:$L21))*1)} -> 1 | P23: {=SUMPRODUCT(ISNUMBER(FIND("으뜸16강", '2004~2025 시즌 결과'!$B21:$L21))*1)} -> 3 | Q23: 1회*(2010) | T23: 1회*(2023) | W23: {=SUMPRODUCT(ISNUMBER(FIND("버금4강", '2004~2025 시즌 결과'!$B21:$L21))*1)} -> 1 | X23: {=SUMPRODUCT(ISNUMBER(FIND("버금8강", '2004~2025 시즌 결과'!$B21:$L21))*1)} -> 0 | Y23: {=SUMPRODUCT(ISNUMBER(FIND("버금16강", '2004~2025 시즌 결과'!$B21:$L21))*1)} -> 3 | Z23: {=SUM(COUNTIF('2004~2025 시즌 결과'!$B21:$L21, {"*버금23강*","*버금24강*","*버금32강*"}))} -> 0 | AA23: {=SUMPRODUCT(ISNUMBER(FIND("으뜸", '2004~2025 시즌 결과'!$B21:$L21))*1)} -> 4 | AB23: {=SUMPRODUCT(ISNUMBER(FIND("버금", '2004~2025 시즌 결과'!$B21:$L21))*1)} -> 5 | AC23: *(2004 으뜸, 2007 버금)
A24: 서경대 | B24: - | G24: - | L24: {=SUMPRODUCT(ISNUMBER(FIND("으뜸우승", '2004~2025 시즌 결과'!$B22:$L22))*1)} -> 0 | M24: {=SUMPRODUCT(ISNUMBER(FIND("으뜸준우승", '2004~2025 시즌 결과'!$B22:$L22))*1)} -> 0 | N24: {=SUMPRODUCT(ISNUMBER(FIND("으뜸4강", '2004~2025 시즌 결과'!$B22:$L22))*1)} -> 0 | O24: {=SUMPRODUCT(ISNUMBER(FIND("으뜸8강", '2004~2025 시즌 결과'!$B22:$L22))*1)} -> 0 | P24: {=SUMPRODUCT(ISNUMBER(FIND("으뜸16강", '2004~2025 시즌 결과'!$B22:$L22))*1)} -> 0 | Q24: - | T24: - | W24: {=SUMPRODUCT(ISNUMBER(FIND("버금4강", '2004~2025 시즌 결과'!$B22:$L22))*1)} -> 0 | X24: {=SUMPRODUCT(ISNUMBER(FIND("버금8강", '2004~2025 시즌 결과'!$B22:$L22))*1)} -> 0 | Y24: {=SUMPRODUCT(ISNUMBER(FIND("버금16강", '2004~2025 시즌 결과'!$B22:$L22))*1)} -> 6 | Z24: {=SUM(COUNTIF('2004~2025 시즌 결과'!$B22:$L22, {"*버금23강*","*버금24강*","*버금32강*"}))} -> 0 | AA24: {=SUMPRODUCT(ISNUMBER(FIND("으뜸", '2004~2025 시즌 결과'!$B22:$L22))*1)} -> 0 | AB24: {=SUMPRODUCT(ISNUMBER(FIND("버금", '2004~2025 시즌 결과'!$B22:$L22))*1)} -> 6
A25: 서일대 | B25: - | G25: - | L25: {=SUMPRODUCT(ISNUMBER(FIND("으뜸우승", '2004~2025 시즌 결과'!$B23:$L23))*1)} -> 0 | M25: {=SUMPRODUCT(ISNUMBER(FIND("으뜸준우승", '2004~2025 시즌 결과'!$B23:$L23))*1)} -> 0 | N25: {=SUMPRODUCT(ISNUMBER(FIND("으뜸4강", '2004~2025 시즌 결과'!$B23:$L23))*1)} -> 0 | O25: {=SUMPRODUCT(ISNUMBER(FIND("으뜸8강", '2004~2025 시즌 결과'!$B23:$L23))*1)} -> 0 | P25: {=SUMPRODUCT(ISNUMBER(FIND("으뜸16강", '2004~2025 시즌 결과'!$B23:$L23))*1)} -> 0 | Q25: - | T25: - | W25: {=SUMPRODUCT(ISNUMBER(FIND("버금4강", '2004~2025 시즌 결과'!$B23:$L23))*1)} -> 0 | X25: {=SUMPRODUCT(ISNUMBER(FIND("버금8강", '2004~2025 시즌 결과'!$B23:$L23))*1)} -> 0 | Y25: {=SUMPRODUCT(ISNUMBER(FIND("버금16강", '2004~2025 시즌 결과'!$B23:$L23))*1)} -> 0 | Z25: {=SUM(COUNTIF('2004~2025 시즌 결과'!$B23:$L23, {"*버금23강*","*버금24강*","*버금32강*"}))} -> 0 | AA25: {=SUMPRODUCT(ISNUMBER(FIND("으뜸", '2004~2025 시즌 결과'!$B23:$L23))*1)} -> 0 | AB25: {=SUMPRODUCT(ISNUMBER(FIND("버금", '2004~2025 시즌 결과'!$B23:$L23))*1)} -> 0 | AC25: *탈퇴
A26: 서울과학기술대 | B26: 4회*(2012,2015,2017,2018) | G26: 1회*(2010) | L26: {=SUMPRODUCT(ISNUMBER(FIND("으뜸우승", '2004~2025 시즌 결과'!$B24:$L24))*1)} -> 3 | M26: {=SUMPRODUCT(ISNUMBER(FIND("으뜸준우승", '2004~2025 시즌 결과'!$B24:$L24))*1)} -> 0 | N26: {=SUMPRODUCT(ISNUMBER(FIND("으뜸4강", '2004~2025 시즌 결과'!$B24:$L24))*1)} -> 0 | O26: {=SUMPRODUCT(ISNUMBER(FIND("으뜸8강", '2004~2025 시즌 결과'!$B24:$L24))*1)} -> 2 | P26: {=SUMPRODUCT(ISNUMBER(FIND("으뜸16강", '2004~2025 시즌 결과'!$B24:$L24))*1)} -> 2 | Q26: 1회*(2022) | T26: 1회*(2005) | W26: {=SUMPRODUCT(ISNUMBER(FIND("버금4강", '2004~2025 시즌 결과'!$B24:$L24))*1)} -> 0 | X26: {=SUMPRODUCT(ISNUMBER(FIND("버금8강", '2004~2025 시즌 결과'!$B24:$L24))*1)} -> 1 | Y26: {=SUMPRODUCT(ISNUMBER(FIND("버금16강", '2004~2025 시즌 결과'!$B24:$L24))*1)} -> 1 | Z26: {=SUM(COUNTIF('2004~2025 시즌 결과'!$B24:$L24, {"*버금23강*","*버금24강*","*버금32강*"}))} -> 0 | AA26: {=SUMPRODUCT(ISNUMBER(FIND("으뜸", '2004~2025 시즌 결과'!$B24:$L24))*1)} -> 7 | AB26: {=SUMPRODUCT(ISNUMBER(FIND("버금", '2004~2025 시즌 결과'!$B24:$L24))*1)} -> 3 | AC26: *(2004,2007 버금)
A27: 서울대 | B27: 1회*(1998추계) | G27: 1회(*2000추계) | L27: {=SUMPRODUCT(ISNUMBER(FIND("으뜸우승", '2004~2025 시즌 결과'!$B25:$L25))*1)} -> 0 | M27: {=SUMPRODUCT(ISNUMBER(FIND("으뜸준우승", '2004~2025 시즌 결과'!$B25:$L25))*1)} -> 0 | N27: {=SUMPRODUCT(ISNUMBER(FIND("으뜸4강", '2004~2025 시즌 결과'!$B25:$L25))*1)} -> 0 | O27: {=SUMPRODUCT(ISNUMBER(FIND("으뜸8강", '2004~2025 시즌 결과'!$B25:$L25))*1)} -> 0 | P27: {=SUMPRODUCT(ISNUMBER(FIND("으뜸16강", '2004~2025 시즌 결과'!$B25:$L25))*1)} -> 0 | Q27: - | T27: - | W27: {=SUMPRODUCT(ISNUMBER(FIND("버금4강", '2004~2025 시즌 결과'!$B25:$L25))*1)} -> 0 | X27: {=SUMPRODUCT(ISNUMBER(FIND("버금8강", '2004~2025 시즌 결과'!$B25:$L25))*1)} -> 0 | Y27: {=SUMPRODUCT(ISNUMBER(FIND("버금16강", '2004~2025 시즌 결과'!$B25:$L25))*1)} -> 0 | Z27: {=SUM(COUNTIF('2004~2025 시즌 결과'!$B25:$L25, {"*버금23강*","*버금24강*","*버금32강*"}))} -> 0 | AA27: {=SUMPRODUCT(ISNUMBER(FIND("으뜸", '2004~2025 시즌 결과'!$B25:$L25))*1)} -> 0 | AB27: {=SUMPRODUCT(ISNUMBER(FIND("버금", '2004~2025 시즌 결과'!$B25:$L25))*1)} -> 0 | AC27: *(2004 으뜸) / *탈퇴
A28: 서울시립대 | B28: - | G28: 1회(*2025) | L28: {=SUMPRODUCT(ISNUMBER(FIND("으뜸우승", '2004~2025 시즌 결과'!$B26:$L26))*1)} -> 0 | M28: {=SUMPRODUCT(ISNUMBER(FIND("으뜸준우승", '2004~2025 시즌 결과'!$B26:$L26))*1)} -> 1 | N28: {=SUMPRODUCT(ISNUMBER(FIND("으뜸4강", '2004~2025 시즌 결과'!$B26:$L26))*1)} -> 0 | O28: {=SUMPRODUCT(ISNUMBER(FIND("으뜸8강", '2004~2025 시즌 결과'!$B26:$L26))*1)} -> 1 | P28: {=SUMPRODUCT(ISNUMBER(FIND("으뜸16강", '2004~2025 시즌 결과'!$B26:$L26))*1)} -> 0 | Q28: - | T28: - | W28: {=SUMPRODUCT(ISNUMBER(FIND("버금4강", '2004~2025 시즌 결과'!$B26:$L26))*1)} -> 1 | X28: {=SUMPRODUCT(ISNUMBER(FIND("버금8강", '2004~2025 시즌 결과'!$B26:$L26))*1)} -> 3 | Y28: {=SUMPRODUCT(ISNUMBER(FIND("버금16강", '2004~2025 시즌 결과'!$B26:$L26))*1)} -> 0 | Z28: {=SUM(COUNTIF('2004~2025 시즌 결과'!$B26:$L26, {"*버금23강*","*버금24강*","*버금32강*"}))} -> 0 | AA28: {=SUMPRODUCT(ISNUMBER(FIND("으뜸", '2004~2025 시즌 결과'!$B26:$L26))*1)} -> 2 | AB28: {=SUMPRODUCT(ISNUMBER(FIND("버금", '2004~2025 시즌 결과'!$B26:$L26))*1)} -> 4 | AC28: 으뜸 4강 진행중
A29: 서울예술대 | B29: - | G29: - | L29: {=SUMPRODUCT(ISNUMBER(FIND("으뜸우승", '2004~2025 시즌 결과'!$B27:$L27))*1)} -> 0 | M29: {=SUMPRODUCT(ISNUMBER(FIND("으뜸준우승", '2004~2025 시즌 결과'!$B27:$L27))*1)} -> 0 | N29: {=SUMPRODUCT(ISNUMBER(FIND("으뜸4강", '2004~2025 시즌 결과'!$B27:$L27))*1)} -> 0 | O29: {=SUMPRODUCT(ISNUMBER(FIND("으뜸8강", '2004~2025 시즌 결과'!$B27:$L27))*1)} -> 0 | P29: {=SUMPRODUCT(ISNUMBER(FIND("으뜸16강", '2004~2025 시즌 결과'!$B27:$L27))*1)} -> 0 | Q29: - | T29: - | W29: {=SUMPRODUCT(ISNUMBER(FIND("버금4강", '2004~2025 시즌 결과'!$B27:$L27))*1)} -> 0 | X29: {=SUMPRODUCT(ISNUMBER(FIND("버금8강", '2004~2025 시즌 결과'!$B27:$L27))*1)} -> 0 | Y29: {=SUMPRODUCT(ISNUMBER(FIND("버금16강", '2004~2025 시즌 결과'!$B27:$L27))*1)} -> 0 | Z29: {=SUM(COUNTIF('2004~2025 시즌 결과'!$B27:$L27, {"*버금23강*","*버금24강*","*버금32강*"}))} -> 0 | AA29: {=SUMPRODUCT(ISNUMBER(FIND("으뜸", '2004~2025 시즌 결과'!$B27:$L27))*1)} -> 0 | AB29: {=SUMPRODUCT(ISNUMBER(FIND("버금", '2004~2025 시즌 결과'!$B27:$L27))*1)} -> 0 | AC29: *탈퇴
A30: 성균관대 | B30: 5회*(1984추계,1984춘계,1989춘계,1997춘계,2019) | G30: 7회*(1982춘계,1982춘계,1982추계,1985추계,1987춘계,1990춘계,2001춘계) | L30: {=SUMPRODUCT(ISNUMBER(FIND("으뜸우승", '2004~2025 시즌 결과'!$B28:$L28))*1)} -> 1 | M30: {=SUMPRODUCT(ISNUMBER(FIND("으뜸준우승", '2004~2025 시즌 결과'!$B28:$L28))*1)} -> 0 | N30: {=SUMPRODUCT(ISNUMBER(FIND("으뜸4강", '2004~2025 시즌 결과'!$B28:$L28))*1)} -> 2 | O30: {=SUMPRODUCT(ISNUMBER(FIND("으뜸8강", '2004~2025 시즌 결과'!$B28:$L28))*1)} -> 1 | P30: {=SUMPRODUCT(ISNUMBER(FIND("으뜸16강", '2004~2025 시즌 결과'!$B28:$L28))*1)} -> 3 | Q30: - | T30: - | W30: {=SUMPRODUCT(ISNUMBER(FIND("버금4강", '2004~2025 시즌 결과'!$B28:$L28))*1)} -> 0 | X30: {=SUMPRODUCT(ISNUMBER(FIND("버금8강", '2004~2025 시즌 결과'!$B28:$L28))*1)} -> 0 | Y30: {=SUMPRODUCT(ISNUMBER(FIND("버금16강", '2004~2025 시즌 결과'!$B28:$L28))*1)} -> 2 | Z30: {=SUM(COUNTIF('2004~2025 시즌 결과'!$B28:$L28, {"*버금23강*","*버금24강*","*버금32강*"}))} -> 0 | AA30: {=SUMPRODUCT(ISNUMBER(FIND("으뜸", '2004~2025 시즌 결과'!$B28:$L28))*1)} -> 7 | AB30: {=SUMPRODUCT(ISNUMBER(FIND("버금", '2004~2025 시즌 결과'!$B28:$L28))*1)} -> 2 | AC30: *(2004 으뜸, 2007 버금)
A31: 세종대 | B31: 1회(*2025) | G31: 1회*(2017) | L31: {=SUMPRODUCT(ISNUMBER(FIND("으뜸우승", '2004~2025 시즌 결과'!$B29:$L29))*1)} -> 1 | M31: {=SUMPRODUCT(ISNUMBER(FIND("으뜸준우승", '2004~2025 시즌 결과'!$B29:$L29))*1)} -> 1 | N31: {=SUMPRODUCT(ISNUMBER(FIND("으뜸4강", '2004~2025 시즌 결과'!$B29:$L29))*1)} -> 0 | O31: {=SUMPRODUCT(ISNUMBER(FIND("으뜸8강", '2004~2025 시즌 결과'!$B29:$L29))*1)} -> 2 | P31: {=SUMPRODUCT(ISNUMBER(FIND("으뜸16강", '2004~2025 시즌 결과'!$B29:$L29))*1)} -> 3 | Q31: - | T31: - | W31: {=SUMPRODUCT(ISNUMBER(FIND("버금4강", '2004~2025 시즌 결과'!$B29:$L29))*1)} -> 1 | X31: {=SUMPRODUCT(ISNUMBER(FIND("버금8강", '2004~2025 시즌 결과'!$B29:$L29))*1)} -> 1 | Y31: {=SUMPRODUCT(ISNUMBER(FIND("버금16강", '2004~2025 시즌 결과'!$B29:$L29))*1)} -> 1 | Z31: {=SUM(COUNTIF('2004~2025 시즌 결과'!$B29:$L29, {"*버금23강*","*버금24강*","*버금32강*"}))} -> 0 | AA31: {=SUMPRODUCT(ISNUMBER(FIND("으뜸", '2004~2025 시즌 결과'!$B29:$L29))*1)} -> 7 | AB31: {=SUMPRODUCT(ISNUMBER(FIND("버금", '2004~2025 시즌 결과'!$B29:$L29))*1)} -> 3 | AC31: *(2004 버금, 2007 으뜸) / 으뜸 4강 진행중
A32: 숭실대 | B32: 2회*(1991추계,2016) | G32: 5회*(1984추계,1997춘계,2012,2013,2023) | L32: {=SUMPRODUCT(ISNUMBER(FIND("으뜸우승", '2004~2025 시즌 결과'!$B30:$L30))*1)} -> 1 | M32: {=SUMPRODUCT(ISNUMBER(FIND("으뜸준우승", '2004~2025 시즌 결과'!$B30:$L30))*1)} -> 1 | N32: {=SUMPRODUCT(ISNUMBER(FIND("으뜸4강", '2004~2025 시즌 결과'!$B30:$L30))*1)} -> 0 | O32: {=SUMPRODUCT(ISNUMBER(FIND("으뜸8강", '2004~2025 시즌 결과'!$B30:$L30))*1)} -> 3 | P32: {=SUMPRODUCT(ISNUMBER(FIND("으뜸16강", '2004~2025 시즌 결과'!$B30:$L30))*1)} -> 5 | Q32: - | T32: 1회*(2006) | W32: {=SUMPRODUCT(ISNUMBER(FIND("버금4강", '2004~2025 시즌 결과'!$B30:$L30))*1)} -> 0 | X32: {=SUMPRODUCT(ISNUMBER(FIND("버금8강", '2004~2025 시즌 결과'!$B30:$L30))*1)} -> 0 | Y32: {=SUMPRODUCT(ISNUMBER(FIND("버금16강", '2004~2025 시즌 결과'!$B30:$L30))*1)} -> 0 | Z32: {=SUM(COUNTIF('2004~2025 시즌 결과'!$B30:$L30, {"*버금23강*","*버금24강*","*버금32강*"}))} -> 0 | AA32: {=SUMPRODUCT(ISNUMBER(FIND("으뜸", '2004~2025 시즌 결과'!$B30:$L30))*1)} -> 10 | AB32: {=SUMPRODUCT(ISNUMBER(FIND("버금", '2004~2025 시즌 결과'!$B30:$L30))*1)} -> 0 | AC32: *(2004 버금, 2007 으뜸)
A33: 아주대 | B33: - | G33: 2회*(1986춘계,1994춘계) | L33: {=SUMPRODUCT(ISNUMBER(FIND("으뜸우승", '2004~2025 시즌 결과'!$B31:$L31))*1)} -> 0 | M33: {=SUMPRODUCT(ISNUMBER(FIND("으뜸준우승", '2004~2025 시즌 결과'!$B31:$L31))*1)} -> 0 | N33: {=SUMPRODUCT(ISNUMBER(FIND("으뜸4강", '2004~2025 시즌 결과'!$B31:$L31))*1)} -> 0 | O33: {=SUMPRODUCT(ISNUMBER(FIND("으뜸8강", '2004~2025 시즌 결과'!$B31:$L31))*1)} -> 1 | P33: {=SUMPRODUCT(ISNUMBER(FIND("으뜸16강", '2004~2025 시즌 결과'!$B31:$L31))*1)} -> 2 | Q33: 1회*(2015) | T33: 1회*(2017) | W33: {=SUMPRODUCT(ISNUMBER(FIND("버금4강", '2004~2025 시즌 결과'!$B31:$L31))*1)} -> 0 | X33: {=SUMPRODUCT(ISNUMBER(FIND("버금8강", '2004~2025 시즌 결과'!$B31:$L31))*1)} -> 3 | Y33: {=SUMPRODUCT(ISNUMBER(FIND("버금16강", '2004~2025 시즌 결과'!$B31:$L31))*1)} -> 0 | Z33: {=SUM(COUNTIF('2004~2025 시즌 결과'!$B31:$L31, {"*버금23강*","*버금24강*","*버금32강*"}))} -> 0 | AA33: {=SUMPRODUCT(ISNUMBER(FIND("으뜸", '2004~2025 시즌 결과'!$B31:$L31))*1)} -> 3 | AB33: {=SUMPRODUCT(ISNUMBER(FIND("버금", '2004~2025 시즌 결과'!$B31:$L31))*1)} -> 5 | AC33: *(2004,2007 으뜸)
A34: 연세대 | B34: 5회*(2000춘계,2000추계,2009,2011,2013) | G34: 1회*(2007) | L34: {=SUMPRODUCT(ISNUMBER(FIND("으뜸우승", '2004~2025 시즌 결과'!$B32:$L32))*1)} -> 0 | M34: {=SUMPRODUCT(ISNUMBER(FIND("으뜸준우승", '2004~2025 시즌 결과'!$B32:$L32))*1)} -> 0 | N34: {=SUMPRODUCT(ISNUMBER(FIND("으뜸4강", '2004~2025 시즌 결과'!$B32:$L32))*1)} -> 1 | O34: {=SUMPRODUCT(ISNUMBER(FIND("으뜸8강", '2004~2025 시즌 결과'!$B32:$L32))*1)} -> 4 | P34: {=SUMPRODUCT(ISNUMBER(FIND("으뜸16강", '2004~2025 시즌 결과'!$B32:$L32))*1)} -> 4 | Q34: - | T34: - | W34: {=SUMPRODUCT(ISNUMBER(FIND("버금4강", '2004~2025 시즌 결과'!$B32:$L32))*1)} -> 0 | X34: {=SUMPRODUCT(ISNUMBER(FIND("버금8강", '2004~2025 시즌 결과'!$B32:$L32))*1)} -> 0 | Y34: {=SUMPRODUCT(ISNUMBER(FIND("버금16강", '2004~2025 시즌 결과'!$B32:$L32))*1)} -> 0 | Z34: {=SUM(COUNTIF('2004~2025 시즌 결과'!$B32:$L32, {"*버금23강*","*버금24강*","*버금32강*"}))} -> 0 | AA34: {=SUMPRODUCT(ISNUMBER(FIND("으뜸", '2004~2025 시즌 결과'!$B32:$L32))*1)} -> 9 | AB34: {=SUMPRODUCT(ISNUMBER(FIND("버금", '2004~2025 시즌 결과'!$B32:$L32))*1)} -> 0 | AC34: *(2004 으뜸) / 으뜸 4강 진행중
A35: 용인대 | B35: - | G35: - | L35: {=SUMPRODUCT(ISNUMBER(FIND("으뜸우승", '2004~2025 시즌 결과'!$B33:$L33))*1)} -> 0 | M35: {=SUMPRODUCT(ISNUMBER(FIND("으뜸준우승", '2004~2025 시즌 결과'!$B33:$L33))*1)} -> 0 | N35: {=SUMPRODUCT(ISNUMBER(FIND("으뜸4강", '2004~2025 시즌 결과'!$B33:$L33))*1)} -> 0 | O35: {=SUMPRODUCT(ISNUMBER(FIND("으뜸8강", '2004~2025 시즌 결과'!$B33:$L33))*1)} -> 0 | P35: {=SUMPRODUCT(ISNUMBER(FIND("으뜸16강", '2004~2025 시즌 결과'!$B33:$L33))*1)} -> 0 | Q35: - | T35: - | W35: {=SUMPRODUCT(ISNUMBER(FIND("버금4강", '2004~2025 시즌 결과'!$B33:$L33))*1)} -> 0 | X35: {=SUMPRODUCT(ISNUMBER(FIND("버금8강", '2004~2025 시즌 결과'!$B33:$L33))*1)} -> 0 | Y35: {=SUMPRODUCT(ISNUMBER(FIND("버금16강", '2004~2025 시즌 결과'!$B33:$L33))*1)} -> 0 | Z35: {=SUM(COUNTIF('2004~2025 시즌 결과'!$B33:$L33, {"*버금23강*","*버금24강*","*버금32강*"}))} -> 0 | AA35: {=SUMPRODUCT(ISNUMBER(FIND("으뜸", '2004~2025 시즌 결과'!$B33:$L33))*1)} -> 0 | AB35: {=SUMPRODUCT(ISNUMBER(FIND("버금", '2004~2025 시즌 결과'!$B33:$L33))*1)} -> 0 | AC35: *탈퇴
A36: 육군사관학교 | B36: - | G36: - | L36: {=SUMPRODUCT(ISNUMBER(FIND("으뜸우승", '2004~2025 시즌 결과'!$B34:$L34))*1)} -> 0 | M36: {=SUMPRODUCT(ISNUMBER(FIND("으뜸준우승", '2004~2025 시즌 결과'!$B34:$L34))*1)} -> 0 | N36: {=SUMPRODUCT(ISNUMBER(FIND("으뜸4강", '2004~2025 시즌 결과'!$B34:$L34))*1)} -> 0 | O36: {=SUMPRODUCT(ISNUMBER(FIND("으뜸8강", '2004~2025 시즌 결과'!$B34:$L34))*1)} -> 0 | P36: {=SUMPRODUCT(ISNUMBER(FIND("으뜸16강", '2004~2025 시즌 결과'!$B34:$L34))*1)} -> 0 | Q36: - | T36: - | W36: {=SUMPRODUCT(ISNUMBER(FIND("버금4강", '2004~2025 시즌 결과'!$B34:$L34))*1)} -> 0 | X36: {=SUMPRODUCT(ISNUMBER(FIND("버금8강", '2004~2025 시즌 결과'!$B34:$L34))*1)} -> 0 | Y36: {=SUMPRODUCT(ISNUMBER(FIND("버금16강", '2004~2025 시즌 결과'!$B34:$L34))*1)} -> 0 | Z36: {=SUM(COUNTIF('2004~2025 시즌 결과'!$B34:$L34, {"*버금23강*","*버금24강*","*버금32강*"}))} -> 0 | AA36: {=SUMPRODUCT(ISNUMBER(FIND("으뜸", '2004~2025 시즌 결과'!$B34:$L34))*1)} -> 0 | AB36: {=SUMPRODUCT(ISNUMBER(FIND("버금", '2004~2025 시즌 결과'!$B34:$L34))*1)} -> 0 | AC36: *탈퇴
... A41: 한국공학대 | B41: - | G41: - | L41: {=SUMPRODUCT(ISNUMBER(FIND("으뜸우승", '2004~2025 시즌 결과'!$B39:$L39))*1)} -> 0 | M41: {=SUMPRODUCT(ISNUMBER(FIND("으뜸준우승", '2004~2025 시즌 결과'!$B39:$L39))*1)} -> 0 | N41: {=SUMPRODUCT(ISNUMBER(FIND("으뜸4강", '2004~2025 시즌 결과'!$B39:$L39))*1)} -> 1 | O41: {=SUMPRODUCT(ISNUMBER(FIND("으뜸8강", '2004~2025 시즌 결과'!$B39:$L39))*1)} -> 1 | P41: {=SUMPRODUCT(ISNUMBER(FIND("으뜸16강", '2004~2025 시즌 결과'!$B39:$L39))*1)} -> 0 | Q41: 2회*(2014,2017) | T41: - | W41: {=SUMPRODUCT(ISNUMBER(FIND("버금4강", '2004~2025 시즌 결과'!$B39:$L39))*1)} -> 1 | X41: {=SUMPRODUCT(ISNUMBER(FIND("버금8강", '2004~2025 시즌 결과'!$B39:$L39))*1)} -> 2 | Y41: {=SUMPRODUCT(ISNUMBER(FIND("버금16강", '2004~2025 시즌 결과'!$B39:$L39))*1)} -> 1 | Z41: {=SUM(COUNTIF('2004~2025 시즌 결과'!$B39:$L39, {"*버금23강*","*버금24강*","*버금32강*"}))} -> 0 | AA41: {=SUMPRODUCT(ISNUMBER(FIND("으뜸", '2004~2025 시즌 결과'!$B39:$L39))*1)} -> 2 | AB41: {=SUMPRODUCT(ISNUMBER(FIND("버금", '2004~2025 시즌 결과'!$B39:$L39))*1)} -> 5 | AC41: *(전 한국산업기술대) / 버금 4강 진행중
A42: 한국교통대 | B42: - | G42: - | L42: {=SUMPRODUCT(ISNUMBER(FIND("으뜸우승", '2004~2025 시즌 결과'!$B40:$L40))*1)} -> 0 | M42: {=SUMPRODUCT(ISNUMBER(FIND("으뜸준우승", '2004~2025 시즌 결과'!$B40:$L40))*1)} -> 0 | N42: {=SUMPRODUCT(ISNUMBER(FIND("으뜸4강", '2004~2025 시즌 결과'!$B40:$L40))*1)} -> 0 | O42: {=SUMPRODUCT(ISNUMBER(FIND("으뜸8강", '2004~2025 시즌 결과'!$B40:$L40))*1)} -> 0 | P42: {=SUMPRODUCT(ISNUMBER(FIND("으뜸16강", '2004~2025 시즌 결과'!$B40:$L40))*1)} -> 1 | Q42: - | T42: - | W42: {=SUMPRODUCT(ISNUMBER(FIND("버금4강", '2004~2025 시즌 결과'!$B40:$L40))*1)} -> 2 | X42: {=SUMPRODUCT(ISNUMBER(FIND("버금8강", '2004~2025 시즌 결과'!$B40:$L40))*1)} -> 0 | Y42: {=SUMPRODUCT(ISNUMBER(FIND("버금16강", '2004~2025 시즌 결과'!$B40:$L40))*1)} -> 2 | Z42: {=SUM(COUNTIF('2004~2025 시즌 결과'!$B40:$L40, {"*버금23강*","*버금24강*","*버금32강*"}))} -> 0 | AA42: {=SUMPRODUCT(ISNUMBER(FIND("으뜸", '2004~2025 시즌 결과'!$B40:$L40))*1)} -> 1 | AB42: {=SUMPRODUCT(ISNUMBER(FIND("버금", '2004~2025 시즌 결과'!$B40:$L40))*1)} -> 4
A43: 한국외국어대글로벌 | B43: - | G43: 1회*(1985춘계) | L43: {=SUMPRODUCT(ISNUMBER(FIND("으뜸우승", '2004~2025 시즌 결과'!$B41:$L41))*1)} -> 0 | M43: {=SUMPRODUCT(ISNUMBER(FIND("으뜸준우승", '2004~2025 시즌 결과'!$B41:$L41))*1)} -> 0 | N43: {=SUMPRODUCT(ISNUMBER(FIND("으뜸4강", '2004~2025 시즌 결과'!$B41:$L41))*1)} -> 0 | O43: {=SUMPRODUCT(ISNUMBER(FIND("으뜸8강", '2004~2025 시즌 결과'!$B41:$L41))*1)} -> 0 | P43: {=SUMPRODUCT(ISNUMBER(FIND("으뜸16강", '2004~2025 시즌 결과'!$B41:$L41))*1)} -> 1 | Q43: - | T43: 2회*(2010,2025) | W43: {=SUMPRODUCT(ISNUMBER(FIND("버금4강", '2004~2025 시즌 결과'!$B41:$L41))*1)} -> 0 | X43: {=SUMPRODUCT(ISNUMBER(FIND("버금8강", '2004~2025 시즌 결과'!$B41:$L41))*1)} -> 1 | Y43: {=SUMPRODUCT(ISNUMBER(FIND("버금16강", '2004~2025 시즌 결과'!$B41:$L41))*1)} -> 4 | Z43: {=SUM(COUNTIF('2004~2025 시즌 결과'!$B41:$L41, {"*버금23강*","*버금24강*","*버금32강*"}))} -> 0 | AA43: {=SUMPRODUCT(ISNUMBER(FIND("으뜸", '2004~2025 시즌 결과'!$B41:$L41))*1)} -> 1 | AB43: {=SUMPRODUCT(ISNUMBER(FIND("버금", '2004~2025 시즌 결과'!$B41:$L41))*1)} -> 6 | AC43: *(2004 버금, 2007 으뜸) / 버금 4강 진행중
A44: 한국외국어대서울 | B44: 8회*(1981추계,1983춘계,1985추계,1986춘계,1986추계,1990춘계,1992춘계,1992추계) | G44: 4회*(1989추계,1991춘계,1998추계,2022) | L44: {=SUMPRODUCT(ISNUMBER(FIND("으뜸우승", '2004~2025 시즌 결과'!$B42:$L42))*1)} -> 0 | M44: {=SUMPRODUCT(ISNUMBER(FIND("으뜸준우승", '2004~2025 시즌 결과'!$B42:$L42))*1)} -> 1 | N44: {=SUMPRODUCT(ISNUMBER(FIND("으뜸4강", '2004~2025 시즌 결과'!$B42:$L42))*1)} -> 1 | O44: {=SUMPRODUCT(ISNUMBER(FIND("으뜸8강", '2004~2025 시즌 결과'!$B42:$L42))*1)} -> 2 | P44: {=SUMPRODUCT(ISNUMBER(FIND("으뜸16강", '2004~2025 시즌 결과'!$B42:$L42))*1)} -> 2 | Q44: - | T44: 1회*(2018) | W44: {=SUMPRODUCT(ISNUMBER(FIND("버금4강", '2004~2025 시즌 결과'!$B42:$L42))*1)} -> 1 | X44: {=SUMPRODUCT(ISNUMBER(FIND("버금8강", '2004~2025 시즌 결과'!$B42:$L42))*1)} -> 1 | Y44: {=SUMPRODUCT(ISNUMBER(FIND("버금16강", '2004~2025 시즌 결과'!$B42:$L42))*1)} -> 1 | Z44: {=SUM(COUNTIF('2004~2025 시즌 결과'!$B42:$L42, {"*버금23강*","*버금24강*","*버금32강*"}))} -> 0 | AA44: {=SUMPRODUCT(ISNUMBER(FIND("으뜸", '2004~2025 시즌 결과'!$B42:$L42))*1)} -> 6 | AB44: {=SUMPRODUCT(ISNUMBER(FIND("버금", '2004~2025 시즌 결과'!$B42:$L42))*1)} -> 4 | AC44: *(2004 버금, 2007 으뜸)
...
